<?xml version="1.0" encoding="utf-8"?>
<!-- This URDF was automatically created by SolidWorks to URDF Exporter! Originally created by Stephen Brawner (brawner@gmail.com) 
     Commit Version: 1.5.0-0-g9aa0fdb  Build Version: 1.5.7004.21443
     For more information, please see http://wiki.ros.org/sw_urdf_exporter -->
<robot
  name="drone_description">
  <link
    name="drone_body">
    <inertial>
      <origin
        xyz="-1.75E-06 3.6406E-17 -0.0066787"
        rpy="0 0 0" />
      <mass
        value="0.16754" />
      <inertia
        ixx="0.00021488"
        ixy="-3.2374E-21"
        ixz="2.2069E-20"
        iyy="0.00066848"
        iyz="-2.1689E-20"
        izz="0.00067365" />
    </inertial>
    <visual>
      <origin
        xyz="0 0 0"
        rpy="0 0 0" />
      <geometry>
        <mesh
          filename="package://drone_description/meshes/drone_body.STL" />
      </geometry>
      <material
        name="">
        <color
          rgba="0 1 0 1" />
      </material>
    </visual>
    <collision>
      <origin
        xyz="0 0 0"
        rpy="0 0 0" />
      <geometry>
        <mesh
          filename="package://drone_description/meshes/drone_body.STL" />
      </geometry>
    </collision>
  </link>
  <link
    name="front_arm">
    <inertial>
      <origin
        xyz="1.1576E-05 -1.6877E-10 0.0052885"
        rpy="0 0 0" />
      <mass
        value="0.048886" />
      <inertia
        ixx="0.0001324"
        ixy="7.4485E-13"
        ixz="-4.5157E-11"
        iyy="2.6042E-06"
        iyz="-5.8498E-16"
        izz="0.00013238" />
    </inertial>
    <visual>
      <origin
        xyz="0 0 0"
        rpy="0 0 0" />
      <geometry>
        <mesh
          filename="package://drone_description/meshes/front_arm.STL" />
      </geometry>
      <material
        name="">
        <color
          rgba="0 1 0 1" />
      </material>
    </visual>
    <collision>
      <origin
        xyz="0 0 0"
        rpy="0 0 0" />
      <geometry>
        <mesh
          filename="package://drone_description/meshes/front_arm.STL" />
      </geometry>
    </collision>
  </link>
  <joint
    name="front_arm_joint"
    type="continuous">
    <origin
      xyz="0.132698263984774 0 -0.00435147882953481"
      rpy="0 0 0" />
    <parent
      link="drone_body" />
    <child
      link="front_arm" />
    <axis
      xyz="0 1 0" />
    <safety_controller
      k_velocity="0" />
  </joint>
  <link
    name="front_right_prop">
    <inertial>
      <origin
        xyz="3.4747E-06 0 0.0015875"
        rpy="0 0 0" />
      <mass
        value="0.0050401" />
      <inertia
        ixx="1.2716E-06"
        ixy="7.621E-22"
        ixz="2.7648E-09"
        iyy="1.2716E-06"
        iyz="1.069E-23"
        izz="2.5348E-06" />
    </inertial>
    <visual>
      <origin
        xyz="0 0 0"
        rpy="0 0 0" />
      <geometry>
        <mesh
          filename="package://drone_description/meshes/front_right_prop.STL" />
      </geometry>
      <material
        name="">
        <color
          rgba="1 0 0 1" />
      </material>
    </visual>
    <collision>
      <origin
        xyz="0 0 0"
        rpy="0 0 0" />
      <geometry>
        <mesh
          filename="package://drone_description/meshes/front_right_prop.STL" />
      </geometry>
    </collision>
  </link>
  <joint
    name="front_right_prop_joint"
    type="continuous">
    <origin
      xyz="4.16969823919255E-05 -0.1325 0.0190499543663921"
      rpy="0 0 0" />
    <parent
      link="front_arm" />
    <child
      link="front_right_prop" />
    <axis
      xyz="0.00218881797337959 0 0.999997604535071" />
    <safety_controller
      k_velocity="0" />
  </joint>
  <link
    name="front_left_prop">
    <inertial>
      <origin
        xyz="3.4747E-06 0 0.0015875"
        rpy="0 0 0" />
      <mass
        value="0.0050401" />
      <inertia
        ixx="1.2716E-06"
        ixy="-6.3008E-23"
        ixz="2.7648E-09"
        iyy="1.2716E-06"
        iyz="-5.8061E-24"
        izz="2.5348E-06" />
    </inertial>
    <visual>
      <origin
        xyz="0 0 0"
        rpy="0 0 0" />
      <geometry>
        <mesh
          filename="package://drone_description/meshes/front_left_prop.STL" />
      </geometry>
      <material
        name="">
        <color
          rgba="1 0 0 1" />
      </material>
    </visual>
    <collision>
      <origin
        xyz="0 0 0"
        rpy="0 0 0" />
      <geometry>
        <mesh
          filename="package://drone_description/meshes/front_left_prop.STL" />
      </geometry>
    </collision>
  </link>
  <joint
    name="front_left_prop_joint"
    type="continuous">
    <origin
      xyz="4.16969823919811E-05 0.1325 0.0190499543663921"
      rpy="0 0 0" />
    <parent
      link="front_arm" />
    <child
      link="front_left_prop" />
    <axis
      xyz="0.00218881797337959 0 0.999997604535071" />
    <safety_controller
      k_velocity="0" />
  </joint>
  <link
    name="front_right_wing">
    <inertial>
      <origin
        xyz="1.9765E-07 3.6082E-16 8.4714E-05"
        rpy="0 0 0" />
      <mass
        value="0.010641" />
      <inertia
        ixx="3.2224E-05"
        ixy="8.3423E-12"
        ixz="-1.7271E-09"
        iyy="1.0035E-06"
        iyz="-1.826E-14"
        izz="3.1435E-05" />
    </inertial>
    <visual>
      <origin
        xyz="0 0 0"
        rpy="0 0 0" />
      <geometry>
        <mesh
          filename="package://drone_description/meshes/front_right_wing.STL" />
      </geometry>
      <material
        name="">
        <color
          rgba="1 0 0 1" />
      </material>
    </visual>
    <collision>
      <origin
        xyz="0 0 0"
        rpy="0 0 0" />
      <geometry>
        <mesh
          filename="package://drone_description/meshes/front_right_wing.STL" />
      </geometry>
    </collision>
  </link>
  <joint
    name="front_right_wing_joint"
    type="fixed">
    <origin
      xyz="-3.7249E-05 -0.1325 -0.017018"
      rpy="0 0 0" />
    <parent
      link="front_arm" />
    <child
      link="front_right_wing" />
    <axis
      xyz="0 0 0" />
    <safety_controller
      k_velocity="0" />
  </joint>
  <link
    name="front_left_wing">
    <inertial>
      <origin
        xyz="1.7418E-07 0 8.4714E-05"
        rpy="0 0 0" />
      <mass
        value="0.010641" />
      <inertia
        ixx="3.2224E-05"
        ixy="8.3423E-12"
        ixz="-1.728E-09"
        iyy="1.0035E-06"
        iyz="-1.826E-14"
        izz="3.1435E-05" />
    </inertial>
    <visual>
      <origin
        xyz="0 0 0"
        rpy="0 0 0" />
      <geometry>
        <mesh
          filename="package://drone_description/meshes/front_left_wing.STL" />
      </geometry>
      <material
        name="">
        <color
          rgba="1 0 0 1" />
      </material>
    </visual>
    <collision>
      <origin
        xyz="0 0 0"
        rpy="0 0 0" />
      <geometry>
        <mesh
          filename="package://drone_description/meshes/front_left_wing.STL" />
      </geometry>
    </collision>
  </link>
  <joint
    name="front_left_wing_joint"
    type="fixed">
    <origin
      xyz="-3.7249E-05 0.1325 -0.017018"
      rpy="0 0 0" />
    <parent
      link="front_arm" />
    <child
      link="front_left_wing" />
    <axis
      xyz="0 0 0" />
    <safety_controller
      k_velocity="0" />
  </joint>
  <link
    name="back_arm">
    <inertial>
      <origin
        xyz="0 0 0"
        rpy="0 0 0" />
      <mass
        value="0" />
      <inertia
        ixx="0"
        ixy="0"
        ixz="0"
        iyy="0"
        iyz="0"
        izz="0" />
    </inertial>
    <visual>
      <origin
        xyz="0 0 0"
        rpy="0 0 0" />
      <geometry>
        <mesh
          filename="package://drone_description/meshes/back_arm.STL" />
      </geometry>
      <material
        name="">
        <color
          rgba="0 1 0 1" />
      </material>
    </visual>
    <collision>
      <origin
        xyz="0 0 0"
        rpy="0 0 0" />
      <geometry>
        <mesh
          filename="package://drone_description/meshes/back_arm.STL" />
      </geometry>
    </collision>
  </link>
  <joint
    name="back_arm_joint"
    type="continuous">
    <origin
      xyz="-0.132701764015227 0 0.0156484811704651"
      rpy="0 0 0" />
    <parent
      link="drone_body" />
    <child
      link="back_arm" />
    <axis
      xyz="0 -1 0" />
    <safety_controller
      k_velocity="0" />
  </joint>
  <link
    name="back_right_prop">
    <inertial>
      <origin
        xyz="5.1074E-06 -2.7756E-17 0.0015875"
        rpy="0 0 0" />
      <mass
        value="0.0050401" />
      <inertia
        ixx="1.2716E-06"
        ixy="1.2974E-22"
        ixz="4.0639E-09"
        iyy="1.2716E-06"
        iyz="7.4795E-23"
        izz="2.5348E-06" />
    </inertial>
    <visual>
      <origin
        xyz="0 0 0"
        rpy="0 0 0" />
      <geometry>
        <mesh
          filename="package://drone_description/meshes/back_right_prop.STL" />
      </geometry>
      <material
        name="">
        <color
          rgba="1 0 0 1" />
      </material>
    </visual>
    <collision>
      <origin
        xyz="0 0 0"
        rpy="0 0 0" />
      <geometry>
        <mesh
          filename="package://drone_description/meshes/back_right_prop.STL" />
      </geometry>
    </collision>
  </link>
  <joint
    name="back_right_prop_joint"
    type="continuous">
    <origin
      xyz="6.12892824355029E-05 -0.1325 0.0190499014071944"
      rpy="0 0 0" />
    <parent
      link="back_arm" />
    <child
      link="back_right_prop" />
    <axis
      xyz="0.00321728516721246 0 0.999994824524684" />
    <safety_controller
      k_velocity="0" />
  </joint>
  <link
    name="back_left_prop">
    <inertial>
      <origin
        xyz="5.1074E-06 0 0.0015875"
        rpy="0 0 0" />
      <mass
        value="0.0050401" />
      <inertia
        ixx="1.2716E-06"
        ixy="1.3018E-22"
        ixz="4.0639E-09"
        iyy="1.2716E-06"
        iyz="2.1392E-22"
        izz="2.5348E-06" />
    </inertial>
    <visual>
      <origin
        xyz="0 0 0"
        rpy="0 0 0" />
      <geometry>
        <mesh
          filename="package://drone_description/meshes/back_left_prop.STL" />
      </geometry>
      <material
        name="">
        <color
          rgba="1 0 0 1" />
      </material>
    </visual>
    <collision>
      <origin
        xyz="0 0 0"
        rpy="0 0 0" />
      <geometry>
        <mesh
          filename="package://drone_description/meshes/back_left_prop.STL" />
      </geometry>
    </collision>
  </link>
  <joint
    name="back_left_prop_joint"
    type="continuous">
    <origin
      xyz="6.12892824354751E-05 0.1325 0.0190499014071944"
      rpy="0 0 0" />
    <parent
      link="back_arm" />
    <child
      link="back_left_prop" />
    <axis
      xyz="0.00321728516721246 0 0.999994824524684" />
    <safety_controller
      k_velocity="0" />
  </joint>
  <link
    name="back_right_wing">
    <inertial>
      <origin
        xyz="2.85E-07 0 8.4713E-05"
        rpy="0 0 0" />
      <mass
        value="0.010641" />
      <inertia
        ixx="3.2224E-05"
        ixy="8.3423E-12"
        ixz="-2.5389E-09"
        iyy="1.0035E-06"
        iyz="-2.684E-14"
        izz="3.1435E-05" />
    </inertial>
    <visual>
      <origin
        xyz="0 0 0"
        rpy="0 0 0" />
      <geometry>
        <mesh
          filename="package://drone_description/meshes/back_right_wing.STL" />
      </geometry>
      <material
        name="">
        <color
          rgba="1 0 0 1" />
      </material>
    </visual>
    <collision>
      <origin
        xyz="0 0 0"
        rpy="0 0 0" />
      <geometry>
        <mesh
          filename="package://drone_description/meshes/back_right_wing.STL" />
      </geometry>
    </collision>
  </link>
  <joint
    name="back_right_wing_joint"
    type="fixed">
    <origin
      xyz="-5.47517589746978E-05 -0.1325 -0.0170179119237633"
      rpy="0 0 0" />
    <parent
      link="back_arm" />
    <child
      link="back_right_wing" />
    <axis
      xyz="0 0 0" />
    <safety_controller
      k_velocity="0" />
  </joint>
  <link
    name="back_left_wing">
    <inertial>
      <origin
        xyz="2.6154E-07 0 8.4714E-05"
        rpy="0 0 0" />
      <mass
        value="0.010641" />
      <inertia
        ixx="3.2224E-05"
        ixy="8.3423E-12"
        ixz="-2.5398E-09"
        iyy="1.0035E-06"
        iyz="-2.684E-14"
        izz="3.1435E-05" />
    </inertial>
    <visual>
      <origin
        xyz="0 0 0"
        rpy="0 0 0" />
      <geometry>
        <mesh
          filename="package://drone_description/meshes/back_left_wing.STL" />
      </geometry>
      <material
        name="">
        <color
          rgba="1 0 0 1" />
      </material>
    </visual>
    <collision>
      <origin
        xyz="0 0 0"
        rpy="0 0 0" />
      <geometry>
        <mesh
          filename="package://drone_description/meshes/back_left_wing.STL" />
      </geometry>
    </collision>
  </link>
  <joint
    name="back_left_wing_joint"
    type="fixed">
    <origin
      xyz="-5.47517589748713E-05 0.1325 -0.0170179119237634"
      rpy="0 0 0" />
    <parent
      link="back_arm" />
    <child
      link="back_left_wing" />
    <axis
      xyz="0 0 0" />
    <safety_controller
      k_velocity="0" />
  </joint>
</robot>