<?xml version="1.0" encoding="utf-8"?>
<!-- This URDF was automatically created by SolidWorks to URDF Exporter! Originally created by Stephen Brawner (brawner@gmail.com) 
     Commit Version: 1.5.0-0-g9aa0fdb  Build Version: 1.5.7004.21443
     For more information, please see http://wiki.ros.org/sw_urdf_exporter -->
<robot
  name="drone_description">
  <link
    name="drone_body">
    <inertial>
      <origin
        xyz="3.9739303772232E-05 -0.00112994714726676 -0.00455425521413035"
        rpy="0 0 0" />
      <mass
        value="0.357445870183079" />
      <inertia
        ixx="0.000431080496676135"
        ixy="5.48449149897168E-05"
        ixz="-3.7324869857622E-10"
        iyy="0.00168484099043515"
        iyz="1.18114705298716E-12"
        izz="0.00169240821714416" />
    </inertial>
    <visual>
      <origin
        xyz="0 0 0"
        rpy="0 0 0" />
      <geometry>
        <mesh
          filename="package://drone_description/meshes/drone_body.STL" />
      </geometry>
      <material
        name="">
        <color
          rgba="0.752941176470588 0.752941176470588 0.752941176470588 1" />
      </material>
    </visual>
    <collision>
      <origin
        xyz="0 0 0"
        rpy="0 0 0" />
      <geometry>
        <mesh
          filename="package://drone_description/meshes/drone_body.STL" />
      </geometry>
    </collision>
  </link>
  <link
    name="front_arm">
    <inertial>
      <origin
        xyz="-3.328156376603E-07 0.00528847069891194 -4.23110765174206E-12"
        rpy="0 0 0" />
      <mass
        value="0.0488863352917365" />
      <inertia
        ixx="0.000132396833896061"
        ixy="-4.99567917547445E-13"
        ixz="-7.39033945209973E-13"
        iyy="0.000132377174520321"
        iyz="-2.4738845028855E-17"
        izz="2.60423234522648E-06" />
    </inertial>
    <visual>
      <origin
        xyz="0 0 0"
        rpy="0 0 0" />
      <geometry>
        <mesh
          filename="package://drone_description/meshes/front_arm.STL" />
      </geometry>
      <material
        name="">
        <color
          rgba="0.752941176470588 0.752941176470588 0.752941176470588 1" />
      </material>
    </visual>
    <collision>
      <origin
        xyz="0 0 0"
        rpy="0 0 0" />
      <geometry>
        <mesh
          filename="package://drone_description/meshes/front_arm.STL" />
      </geometry>
    </collision>
  </link>
  <joint
    name="front_arm_joint"
    type="continuous">
    <origin
      xyz="0.132672408666361 -0.00476080646900178 -0.00245406277845809"
      rpy="1.5707963267949 0 0" />
    <parent
      link="drone_body" />
    <child
      link="front_arm" />
    <axis
      xyz="0 0 -1" />
    <safety_controller
      k_velocity="0" />
  </joint>
  <link
    name="front_right_prop">
    <inertial>
      <origin
        xyz="-2.77555756156289E-17 2.77555756156289E-17 0.0015875"
        rpy="0 0 0" />
      <mass
        value="0.00504005698984341" />
      <inertia
        ixx="1.27162752917409E-06"
        ixy="3.11019910319938E-22"
        ixz="1.7556908501438E-22"
        iyy="1.27162752917409E-06"
        iyz="2.36643125436923E-23"
        izz="2.53478723759932E-06" />
    </inertial>
    <visual>
      <origin
        xyz="0 0 0"
        rpy="0 0 0" />
      <geometry>
        <mesh
          filename="package://drone_description/meshes/front_right_prop.STL" />
      </geometry>
      <material
        name="">
        <color
          rgba="1 1 1 1" />
      </material>
    </visual>
    <collision>
      <origin
        xyz="0 0 0"
        rpy="0 0 0" />
      <geometry>
        <mesh
          filename="package://drone_description/meshes/front_right_prop.STL" />
      </geometry>
    </collision>
  </link>
  <joint
    name="front_right_prop_joint"
    type="continuous">
    <origin
      xyz="0 0.019049999962237 0.1325"
      rpy="-1.5707963267949 0 6.29649045572343E-05" />
    <parent
      link="front_arm" />
    <child
      link="front_right_prop" />
    <axis
      xyz="0 0 1" />
    <safety_controller
      k_velocity="0" />
  </joint>
  <link
    name="front_left_prop">
    <inertial>
      <origin
        xyz="0 2.77555756156289E-17 0.0015875"
        rpy="0 0 0" />
      <mass
        value="0.00504005698984341" />
      <inertia
        ixx="1.2716275291741E-06"
        ixy="-2.11758236813575E-22"
        ixz="1.98239003677162E-22"
        iyy="1.27162752917409E-06"
        iyz="2.84666452991882E-23"
        izz="2.53478723759932E-06" />
    </inertial>
    <visual>
      <origin
        xyz="0 0 0"
        rpy="0 0 0" />
      <geometry>
        <mesh
          filename="package://drone_description/meshes/front_left_prop.STL" />
      </geometry>
      <material
        name="">
        <color
          rgba="1 1 1 1" />
      </material>
    </visual>
    <collision>
      <origin
        xyz="0 0 0"
        rpy="0 0 0" />
      <geometry>
        <mesh
          filename="package://drone_description/meshes/front_left_prop.STL" />
      </geometry>
    </collision>
  </link>
  <joint
    name="front_left_prop_joint"
    type="continuous">
    <origin
      xyz="0 0.0190499999622373 -0.1325"
      rpy="-1.5707963267949 0 6.29649045572343E-05" />
    <parent
      link="front_arm" />
    <child
      link="front_left_prop" />
    <axis
      xyz="0 0 1" />
    <safety_controller
      k_velocity="0" />
  </joint>
  <link
    name="front_right_wing">
    <inertial>
      <origin
        xyz="-2.5687142760078E-07 -6.69619957427425E-07 8.55690921422805E-05"
        rpy="0 0 0" />
      <mass
        value="0.0106409229155552" />
      <inertia
        ixx="3.22240827607208E-05"
        ixy="8.34233189015923E-12"
        ixz="4.40330785296604E-13"
        iyy="1.00346951370682E-06"
        iyz="-3.00146201115274E-21"
        izz="3.14347766518031E-05" />
    </inertial>
    <visual>
      <origin
        xyz="0 0 0"
        rpy="0 0 0" />
      <geometry>
        <mesh
          filename="package://drone_description/meshes/front_right_wing.STL" />
      </geometry>
      <material
        name="">
        <color
          rgba="0.843137254901961 0.815686274509804 0.752941176470588 1" />
      </material>
    </visual>
    <collision>
      <origin
        xyz="0 0 0"
        rpy="0 0 0" />
      <geometry>
        <mesh
          filename="package://drone_description/meshes/front_right_wing.STL" />
      </geometry>
    </collision>
  </link>
  <joint
    name="front_right_wing_joint"
    type="fixed">
    <origin
      xyz="0 -0.0170179999662659 0.1325"
      rpy="-1.5707963267949 0 6.29649045571202E-05" />
    <parent
      link="front_arm" />
    <child
      link="front_right_wing" />
    <axis
      xyz="0 0 0" />
    <safety_controller
      k_velocity="0" />
  </joint>
  <link
    name="front_left_wing">
    <inertial>
      <origin
        xyz="2.56846023199975E-07 6.69619957344159E-07 8.55690884140337E-05"
        rpy="0 0 0" />
      <mass
        value="0.0106409229167305" />
      <inertia
        ixx="3.22240827618886E-05"
        ixy="8.34233188918646E-12"
        ixz="-4.43666864087224E-13"
        iyy="1.00346951311838E-06"
        iyz="-3.89512807323328E-22"
        izz="3.14347766541992E-05" />
    </inertial>
    <visual>
      <origin
        xyz="0 0 0"
        rpy="0 0 0" />
      <geometry>
        <mesh
          filename="package://drone_description/meshes/front_left_wing.STL" />
      </geometry>
      <material
        name="">
        <color
          rgba="0.843137254901961 0.815686274509804 0.752941176470588 1" />
      </material>
    </visual>
    <collision>
      <origin
        xyz="0 0 0"
        rpy="0 0 0" />
      <geometry>
        <mesh
          filename="package://drone_description/meshes/front_left_wing.STL" />
      </geometry>
    </collision>
  </link>
  <joint
    name="front_left_wing_joint"
    type="fixed">
    <origin
      xyz="0 -0.0170179999662655 -0.1325"
      rpy="-1.5707963267949 0 6.29649045573601E-05" />
    <parent
      link="front_arm" />
    <child
      link="front_left_wing" />
    <axis
      xyz="0 0 0" />
    <safety_controller
      k_velocity="0" />
  </joint>
  <link
    name="back_arm">
    <inertial>
      <origin
        xyz="1.01225966386564E-05 0.00528846019484934 1.47609310191532E-10"
        rpy="0 0 0" />
      <mass
        value="0.0488863080383806" />
      <inertia
        ixx="0.000132396769219207"
        ixy="-3.97533673058159E-11"
        ixz="-7.4484792510868E-13"
        iyy="0.000132377109834705"
        iyz="5.11229898613289E-16"
        izz="2.60423206426902E-06" />
    </inertial>
    <visual>
      <origin
        xyz="0 0 0"
        rpy="0 0 0" />
      <geometry>
        <mesh
          filename="package://drone_description/meshes/back_arm.STL" />
      </geometry>
      <material
        name="">
        <color
          rgba="0.752941176470588 0.752941176470588 0.752941176470588 1" />
      </material>
    </visual>
    <collision>
      <origin
        xyz="0 0 0"
        rpy="0 0 0" />
      <geometry>
        <mesh
          filename="package://drone_description/meshes/back_arm.STL" />
      </geometry>
    </collision>
  </link>
  <joint
    name="back_arm_joint"
    type="continuous">
    <origin
      xyz="-0.132404672949994 0.006812708857805 0.0175458972215418"
      rpy="1.5707963267949 0 -0.0872664625997166" />
    <parent
      link="drone_body" />
    <child
      link="back_arm" />
    <axis
      xyz="0 0 1" />
    <safety_controller
      k_velocity="0" />
  </joint>
  <link
    name="back_right_prop">
    <inertial>
      <origin
        xyz="-2.77555756156289E-17 2.77555756156289E-17 0.0015875"
        rpy="0 0 0" />
      <mass
        value="0.00504005698984341" />
      <inertia
        ixx="1.2716275291741E-06"
        ixy="1.27143339610406E-22"
        ixz="1.4475660719678E-22"
        iyy="1.27162752917409E-06"
        iyz="-2.05618043510812E-24"
        izz="2.53478723759932E-06" />
    </inertial>
    <visual>
      <origin
        xyz="0 0 0"
        rpy="0 0 0" />
      <geometry>
        <mesh
          filename="package://drone_description/meshes/back_right_prop.STL" />
      </geometry>
      <material
        name="">
        <color
          rgba="1 1 1 1" />
      </material>
    </visual>
    <collision>
      <origin
        xyz="0 0 0"
        rpy="0 0 0" />
      <geometry>
        <mesh
          filename="package://drone_description/meshes/back_right_prop.STL" />
      </geometry>
    </collision>
  </link>
  <joint
    name="back_right_prop_joint"
    type="continuous">
    <origin
      xyz="3.64629030858987E-05 0.0190499651038185 0.1325"
      rpy="-1.5707963267949 0 -0.00191406432285105" />
    <parent
      link="back_arm" />
    <child
      link="back_right_prop" />
    <axis
      xyz="0.000114168295889295 0 0.9999999934828" />
    <safety_controller
      k_velocity="0" />
  </joint>
  <link
    name="back_left_prop">
    <inertial>
      <origin
        xyz="-5.55111512312578E-17 0 0.0015875"
        rpy="0 0 0" />
      <mass
        value="0.00504005698984341" />
      <inertia
        ixx="1.2716275291741E-06"
        ixy="5.43898856097587E-23"
        ixz="1.70399206185924E-22"
        iyy="1.27162752917409E-06"
        iyz="-4.03801898769125E-23"
        izz="2.53478723759932E-06" />
    </inertial>
    <visual>
      <origin
        xyz="0 0 0"
        rpy="0 0 0" />
      <geometry>
        <mesh
          filename="package://drone_description/meshes/back_left_prop.STL" />
      </geometry>
      <material
        name="">
        <color
          rgba="1 1 1 1" />
      </material>
    </visual>
    <collision>
      <origin
        xyz="0 0 0"
        rpy="0 0 0" />
      <geometry>
        <mesh
          filename="package://drone_description/meshes/back_left_prop.STL" />
      </geometry>
    </collision>
  </link>
  <joint
    name="back_left_prop_joint"
    type="continuous">
    <origin
      xyz="3.6462903085871E-05 0.0190499651038184 -0.1325"
      rpy="-1.5707963267949 0 -0.00191406432285105" />
    <parent
      link="back_arm" />
    <child
      link="back_left_prop" />
    <axis
      xyz="0.000114168295889295 0 0.9999999934828" />
    <safety_controller
      k_velocity="0" />
  </joint>
  <link
    name="back_right_wing">
    <inertial>
      <origin
        xyz="1.21655134022181E-08 5.55111512312578E-17 8.4713814092024E-05"
        rpy="0 0 0" />
      <mass
        value="0.0106410240095179" />
      <inertia
        ixx="3.22240827652041E-05"
        ixy="8.34233189028258E-12"
        ixz="4.9341936635132E-13"
        iyy="1.00346951237549E-06"
        iyz="-8.1684646387411E-22"
        izz="3.14347766576977E-05" />
    </inertial>
    <visual>
      <origin
        xyz="0 0 0"
        rpy="0 0 0" />
      <geometry>
        <mesh
          filename="package://drone_description/meshes/back_right_wing.STL" />
      </geometry>
      <material
        name="">
        <color
          rgba="0.843137254901961 0.815686274509804 0.752941176470588 1" />
      </material>
    </visual>
    <collision>
      <origin
        xyz="0 0 0"
        rpy="0 0 0" />
      <geometry>
        <mesh
          filename="package://drone_description/meshes/back_right_wing.STL" />
      </geometry>
    </collision>
  </link>
  <joint
    name="back_right_wing_joint"
    type="fixed">
    <origin
      xyz="-3.25735267566463E-05 -0.0170179688260777 0.1325"
      rpy="-1.5707963267949 0 -0.00191406432285116" />
    <parent
      link="back_arm" />
    <child
      link="back_right_wing" />
    <axis
      xyz="0 0 0" />
    <safety_controller
      k_velocity="0" />
  </joint>
  <link
    name="back_left_wing">
    <inertial>
      <origin
        xyz="-1.1306933167532E-08 -2.77555756156289E-17 8.47139273856042E-05"
        rpy="0 0 0" />
      <mass
        value="0.0106410239738009" />
      <inertia
        ixx="3.22240827297183E-05"
        ixy="8.34233189062913E-12"
        ixz="-3.92036504730356E-13"
        iyy="1.00346953026033E-06"
        iyz="-2.02427404433868E-21"
        izz="3.14347765848837E-05" />
    </inertial>
    <visual>
      <origin
        xyz="0 0 0"
        rpy="0 0 0" />
      <geometry>
        <mesh
          filename="package://drone_description/meshes/back_left_wing.STL" />
      </geometry>
      <material
        name="">
        <color
          rgba="0.843137254901961 0.815686274509804 0.752941176470588 1" />
      </material>
    </visual>
    <collision>
      <origin
        xyz="0 0 0"
        rpy="0 0 0" />
      <geometry>
        <mesh
          filename="package://drone_description/meshes/back_left_wing.STL" />
      </geometry>
    </collision>
  </link>
  <joint
    name="back_left_wing_joint"
    type="fixed">
    <origin
      xyz="-3.25735267567018E-05 -0.0170179688260779 -0.1325"
      rpy="-1.5707963267949 0 -0.00191406432285116" />
    <parent
      link="back_arm" />
    <child
      link="back_left_wing" />
    <axis
      xyz="0 0 0" />
    <safety_controller
      k_velocity="0" />
  </joint>
</robot>